Workbook

Sheet Dashboard
A1: AUTONOMOUS DRIVING OBJECT ANNOTATION DASHBOARD
A2: Illustrative dataset | Excel formulas and charts update when records are changed
A4: Total Tasks | C4: Completed | E4: Pending
A5: =Summary!B4 | C5: =Summary!B5 | E5: =Summary!B6
A8: Rejected | C8: Completion Rate | E8: QA Pass Rate
A9: =Summary!B7 | C9: =Summary!B11 | E9: =Summary!B12
A12: How to use
A13: 1. Update records in Annotation_Data.
A14: 2. Use dropdowns to standardize classes, statuses, and QA results.
A15: 3. Review Summary for class counts and status charts.
A16: 4. Use Quality_Check to track review findings and corrective actions.

Sheet Annotation_Data
A1: Task_ID | B1: Date | C1: Scene_ID | D1: Object_ID | E1: Object_Class | F1: Annotator | G1: Annotation_Status | H1: Quality_Result | I1: Bounding_Box_Complete | J1: Label_Confidence | K1: Review_Notes
A2: T001 | B2: 46298 | C2: SC018 | D2: OBJ0001 | E2: Pedestrian | F2: Annotator A | G2: Rejected | H2: Major Error | I2: No | J2: 0.85 | K2: Verify object class
A3: T002 | B3: 46298 | C3: SC008 | D3: OBJ0002 | E3: Truck | F3: Annotator A | G3: Completed | H3: Pass | I3: No | J3: 0.67 | K3: Verify object class
A4: T003 | B4: 46314 | C4: SC013 | D4: OBJ0003 | E4: Car | F4: Annotator A | G4: Rejected | H4: Major Error | I4: Yes | J4: 0.67 | K4: Missing attributes
A5: T004 | B5: 46299 | C5: SC010 | D5: OBJ0004 | E5: Truck | F5: Annotator B | G5: Completed | H5: Pass | I5: Yes | J5: 0.85 | K5: Occluded object
A6: T005 | B6: 46298 | C6: SC002 | D6: OBJ0005 | E6: Truck | F6: Annotator B | G6: Completed | H6: Pass | I6: No | J6: 0.88 | K6: Check box alignment
A7: T006 | B7: 46310 | C7: SC012 | D7: OBJ0006 | E7: Traffic Light | F7: Annotator C | G7: Completed | H7: Pass | I7: Yes | J7: 0.92 | K7: Occluded object
A8: T007 | B8: 46312 | C8: SC016 | D8: OBJ0007 | E8: Traffic Light | F8: Annotator C | G8: Completed | H8: Pass | I8: No | J8: 0.75
A9: T008 | B9: 46306 | C9: SC005 | D9: OBJ0008 | E9: Car | F9: Annotator D | G9: Completed | H9: Pass | I9: No | J9: 0.66 | K9: Occluded object
A10: T009 | B10: 46322 | C10: SC011 | D10: OBJ0009 | E10: Car | F10: Annotator C | G10: Pending | H10: Pass | I10: No | J10: 0.85 | K10: Verify object class
A11: T010 | B11: 46304 | C11: SC016 | D11: OBJ0010 | E11: Traffic Light | F11: Annotator A | G11: Completed | H11: Major Error | I11: Yes | J11: 0.9
A12: T011 | B12: 46310 | C12: SC010 | D12: OBJ0011 | E12: Traffic Sign | F12: Annotator D | G12: Completed | H12: Minor Error | I12: No | J12: 0.66 | K12: Check box alignment
A13: T012 | B13: 46297 | C13: SC007 | D13: OBJ0012 | E13: Pedestrian | F13: Annotator C | G13: Completed | H13: Pass | I13: Yes | J13: 0.9 | K13: Check box alignment
A14: T013 | B14: 46310 | C14: SC013 | D14: OBJ0013 | E14: Bicycle | F14: Annotator C | G14: Rejected | H14: Major Error | I14: Yes | J14: 0.93 | K14: Missing attributes
A15: T014 | B15: 46307 | C15: SC013 | D15: OBJ0014 | E15: Motorcycle | F15: Annotator B | G15: Completed | H15: Pass | I15: Yes | J15: 0.68
A16: T015 | B16: 46322 | C16: SC006 | D16: OBJ0015 | E16: Truck | F16: Annotator C | G16: In Review | H16: Pass | I16: No | J16: 0.65 | K16: Check box alignment
A17: T016 | B17: 46300 | C17: SC017 | D17: OBJ0016 | E17: Motorcycle | F17: Annotator A | G17: Completed | H17: Pass | I17: No | J17: 0.96 | K17: Missing attributes
A18: T017 | B18: 46308 | C18: SC013 | D18: OBJ0017 | E18: Traffic Light | F18: Annotator D | G18: In Review | H18: Pass | I18: Yes | J18: 0.81 | K18: Check box alignment
A19: T018 | B19: 46310 | C19: SC006 | D19: OBJ0018 | E19: Car | F19: Annotator A | G19: Completed | H19: Needs Review | I19: No | J19: 0.85
A20: T019 | B20: 46307 | C20: SC001 | D20: OBJ0019 | E20: Car | F20: Annotator A | G20: Completed | H20: Pass | I20: Yes | J20: 0.86
A21: T020 | B21: 46307 | C21: SC016 | D21: OBJ0020 | E21: Traffic Sign | F21: Annotator A | G21: Completed | H21: Pass | I21: Yes | J21: 0.94 | K21: Check box alignment
A22: T021 | B22: 46299 | C22: SC011 | D22: OBJ0021 | E22: Bicycle | F22: Annotator C | G22: Completed | H22: Pass | I22: No | J22: 0.93
A23: T022 | B23: 46312 | C23: SC012 | D23: OBJ0022 | E23: Motorcycle | F23: Annotator B | G23: Completed | H23: Needs Review | I23: Yes | J23: 0.91
A24: T023 | B24: 46304 | C24: SC017 | D24: OBJ0023 | E24: Traffic Sign | F24: Annotator C | G24: Pending | H24: Minor Error | I24: Yes | J24: 0.77
A25: T024 | B25: 46316 | C25: SC008 | D25: OBJ0024 | E25: Motorcycle | F25: Annotator B | G25: Completed | H25: Pass | I25: Yes | J25: 0.93 | K25: Occluded object
A26: T025 | B26: 46307 | C26: SC001 | D26: OBJ0025 | E26: Traffic Light | F26: Annotator A | G26: Completed | H26: Pass | I26: No | J26: 0.81
A27: T026 | B27: 46321 | C27: SC012 | D27: OBJ0026 | E27: Traffic Sign | F27: Annotator C | G27: In Review | H27: Pass | I27: Yes | J27: 0.72
A28: T027 | B28: 46315 | C28: SC001 | D28: OBJ0027 | E28: Bicycle | F28: Annotator D | G28: Completed | H28: Pass | I28: No | J28: 0.92
A29: T028 | B29: 46321 | C29: SC007 | D29: OBJ0028 | E29: Traffic Light | F29: Annotator D | G29: In Review | H29: Needs Review | I29: Yes | J29: 0.8 | K29: Occluded object
A30: T029 | B30: 46319 | C30: SC013 | D30: OBJ0029 | E30: Pedestrian | F30: Annotator D | G30: Completed | H30: Needs Review | I30: No | J30: 0.9
A31: T030 | B31: 46296 | C31: SC005 | D31: OBJ0030 | E31: Traffic Sign | F31: Annotator D | G31: Completed | H31: Needs Review | I31: Yes | J31: 0.86 | K31: Verify object class
A32: T031 | B32: 46313 | C32: SC018 | D32: OBJ0031 | E32: Bicycle | F32: Annotator B | G32: In Review | H32: Pass | I32: Yes | J32: 0.65 | K32: Occluded object
A33: T032 | B33: 46300 | C33: SC014 | D33: OBJ0032 | E33: Traffic Sign | F33: Annotator B | G33: Completed | H33: Minor Error | I33: Yes | J33: 0.66
A34: T033 | B34: 46306 | C34: SC009 | D34: OBJ0033 | E34: Pedestrian | F34: Annotator D | G34: Completed | H34: Minor Error | I34: Yes | J34: 0.67 | K34: Occluded object
A35: T034 | B35: 46322 | C35: SC017 | D35: OBJ0034 | E35: Pedestrian | F35: Annotator D | G35: Pending | H35: Pass | I35: Yes | J35: 0.83 | K35: Verify object class
A36: T035 | B36: 46301 | C36: SC001 | D36: OBJ0035 | E36: Motorcycle | F36: Annotator B | G36: Completed | H36: Pass | I36: Yes | J36: 0.7 | K36: Verify object class
A37: T036 | B37: 46317 | C37: SC017 | D37: OBJ0036 | E37: Traffic Sign | F37: Annotator D | G37: Completed | H37: Pass | I37: Yes | J37: 0.95
A38: T037 | B38: 46299 | C38: SC017 | D38: OBJ0037 | E38: Truck | F38: Annotator D | G38: Completed | H38: Pass | I38: Yes | J38: 0.91
A39: T038 | B39: 46315 | C39: SC017 | D39: OBJ0038 | E39: Bicycle | F39: Annotator B | G39: Completed | H39: Needs Review | I39: No | J39: 0.8 | K39: Verify object class
A40: T039 | B40: 46318 | C40: SC017 | D40: OBJ0039 | E40: Traffic Light | F40: Annotator C | G40: Completed | H40: Needs Review | I40: Yes | J40: 0.94
...

Sheet Quality_Check
A1: Task_ID | B1: Object_Class | C1: Quality_Result | D1: Issue_Type | E1: Severity | F1: Action_Required | G1: Reviewer
A2: =Annotation_Data!A2 | B2: =Annotation_Data!E2 | C2: =Annotation_Data!H2 | D2: Occlusion issue | E2: Low | F2: Correct label | G2: Reviewer 1
A3: =Annotation_Data!A4 | B3: =Annotation_Data!E4 | C3: =Annotation_Data!H4 | D3: Incorrect label | E3: Low | F3: Correct label | G3: Reviewer 1
A4: =Annotation_Data!A6 | B4: =Annotation_Data!E6 | C4: =Annotation_Data!H6 | D4: Bounding-box issue | E4: Low | F4: Escalate to QA | G4: Reviewer 2
A5: =Annotation_Data!A8 | B5: =Annotation_Data!E8 | C5: =Annotation_Data!H8 | D5: Occlusion issue | E5: Low | F5: Correct label | G5: Reviewer 1
A6: =Annotation_Data!A10 | B6: =Annotation_Data!E10 | C6: =Annotation_Data!H10 | D6: Duplicate annotation | E6: Medium | F6: Correct label | G6: Reviewer 2
A7: =Annotation_Data!A12 | B7: =Annotation_Data!E12 | C7: =Annotation_Data!H12 | D7: Incorrect label | E7: High | F7: Correct label | G7: Reviewer 1
A8: =Annotation_Data!A14 | B8: =Annotation_Data!E14 | C8: =Annotation_Data!H14 | D8: Duplicate annotation | E8: Medium | F8: Correct label | G8: Reviewer 2
A9: =Annotation_Data!A16 | B9: =Annotation_Data!E16 | C9: =Annotation_Data!H16 | D9: Missing object | E9: High | F9: Re-annotate | G9: Reviewer 1
A10: =Annotation_Data!A18 | B10: =Annotation_Data!E18 | C10: =Annotation_Data!H18 | D10: Duplicate annotation | E10: Medium | F10: Escalate to QA | G10: Reviewer 1
A11: =Annotation_Data!A20 | B11: =Annotation_Data!E20 | C11: =Annotation_Data!H20 | D11: Duplicate annotation | E11: High | F11: Verify with guideline | G11: Reviewer 1
A12: =Annotation_Data!A22 | B12: =Annotation_Data!E22 | C12: =Annotation_Data!H22 | D12: Occlusion issue | E12: High | F12: Re-annotate | G12: Reviewer 1
A13: =Annotation_Data!A24 | B13: =Annotation_Data!E24 | C13: =Annotation_Data!H24 | D13: Occlusion issue | E13: Low | F13: Verify with guideline | G13: Reviewer 2
A14: =Annotation_Data!A26 | B14: =Annotation_Data!E26 | C14: =Annotation_Data!H26 | D14: Bounding-box issue | E14: High | F14: Re-annotate | G14: Reviewer 1
A15: =Annotation_Data!A28 | B15: =Annotation_Data!E28 | C15: =Annotation_Data!H28 | D15: Duplicate annotation | E15: Low | F15: Escalate to QA | G15: Reviewer 2
A16: =Annotation_Data!A30 | B16: =Annotation_Data!E30 | C16: =Annotation_Data!H30 | D16: Incorrect label | E16: High | F16: Re-annotate | G16: Reviewer 2
A17: =Annotation_Data!A32 | B17: =Annotation_Data!E32 | C17: =Annotation_Data!H32 | D17: Bounding-box issue | E17: High | F17: Verify with guideline | G17: Reviewer 2
A18: =Annotation_Data!A34 | B18: =Annotation_Data!E34 | C18: =Annotation_Data!H34 | D18: Duplicate annotation | E18: Medium | F18: Correct label | G18: Reviewer 1
A19: =Annotation_Data!A36 | B19: =Annotation_Data!E36 | C19: =Annotation_Data!H36 | D19: Bounding-box issue | E19: Low | F19: Escalate to QA | G19: Reviewer 1
A20: =Annotation_Data!A38 | B20: =Annotation_Data!E38 | C20: =Annotation_Data!H38 | D20: Bounding-box issue | E20: Medium | F20: Correct label | G20: Reviewer 2
A21: =Annotation_Data!A40 | B21: =Annotation_Data!E40 | C21: =Annotation_Data!H40 | D21: Bounding-box issue | E21: Medium | F21: Re-annotate | G21: Reviewer 1
A22: =Annotation_Data!A42 | B22: =Annotation_Data!E42 | C22: =Annotation_Data!H42 | D22: Incorrect label | E22: High | F22: Correct label | G22: Reviewer 1
A23: =Annotation_Data!A44 | B23: =Annotation_Data!E44 | C23: =Annotation_Data!H44 | D23: Occlusion issue | E23: Medium | F23: Verify with guideline | G23: Reviewer 1
A24: =Annotation_Data!A46 | B24: =Annotation_Data!E46 | C24: =Annotation_Data!H46 | D24: Occlusion issue | E24: High | F24: Verify with guideline | G24: Reviewer 1
A25: =Annotation_Data!A48 | B25: =Annotation_Data!E48 | C25: =Annotation_Data!H48 | D25: Bounding-box issue | E25: Low | F25: Escalate to QA | G25: Reviewer 2
A26: =Annotation_Data!A50 | B26: =Annotation_Data!E50 | C26: =Annotation_Data!H50 | D26: Duplicate annotation | E26: Low | F26: Re-annotate | G26: Reviewer 1
A27: =Annotation_Data!A52 | B27: =Annotation_Data!E52 | C27: =Annotation_Data!H52 | D27: Duplicate annotation | E27: High | F27: Escalate to QA | G27: Reviewer 2
A28: =Annotation_Data!A54 | B28: =Annotation_Data!E54 | C28: =Annotation_Data!H54 | D28: Bounding-box issue | E28: High | F28: Re-annotate | G28: Reviewer 2
A29: =Annotation_Data!A56 | B29: =Annotation_Data!E56 | C29: =Annotation_Data!H56 | D29: Bounding-box issue | E29: Medium | F29: Verify with guideline | G29: Reviewer 1
A30: =Annotation_Data!A58 | B30: =Annotation_Data!E58 | C30: =Annotation_Data!H58 | D30: Bounding-box issue | E30: Low | F30: Verify with guideline | G30: Reviewer 2
A31: =Annotation_Data!A60 | B31: =Annotation_Data!E60 | C31: =Annotation_Data!H60 | D31: Duplicate annotation | E31: Low | F31: Re-annotate | G31: Reviewer 1

Sheet Summary
A1: AUTONOMOUS DRIVING OBJECT ANNOTATION TRACKER
A2: Sample portfolio project — replace example records with your own practice data.
A3: Metric | B3: Value
A4: Total annotation tasks | B4: =COUNTA(Annotation_Data!A2:A501)
A5: Completed tasks | B5: =COUNTIF(Annotation_Data!G2:G501,"Completed")
A6: Pending tasks | B6: =COUNTIF(Annotation_Data!G2:G501,"Pending")
A7: Rejected tasks | B7: =COUNTIF(Annotation_Data!G2:G501,"Rejected")
A8: Tasks passed QA | B8: =COUNTIF(Annotation_Data!H2:H501,"Pass")
A9: Tasks with major errors | B9: =COUNTIF(Annotation_Data!H2:H501,"Major Error")
A10: Bounding boxes complete | B10: =COUNTIF(Annotation_Data!I2:I501,"Yes")
A11: Completion rate | B11: =IFERROR(B4/B3,0)
A12: QA pass rate | B12: =IFERROR(B7/B3,0)
A15: Object Class | B15: Task Count | D15: Status | E15: Count
A16: Car | B16: =COUNTIF(Annotation_Data!E2:E501,A16) | D16: Completed | E16: =COUNTIF(Annotation_Data!G2:G501,D16)
A17: Truck | B17: =COUNTIF(Annotation_Data!E2:E501,A17) | D17: In Review | E17: =COUNTIF(Annotation_Data!G2:G501,D17)
A18: Pedestrian | B18: =COUNTIF(Annotation_Data!E2:E501,A18) | D18: Pending | E18: =COUNTIF(Annotation_Data!G2:G501,D18)
A19: Bicycle | B19: =COUNTIF(Annotation_Data!E2:E501,A19) | D19: Rejected | E19: =COUNTIF(Annotation_Data!G2:G501,D19)
A20: Motorcycle | B20: =COUNTIF(Annotation_Data!E2:E501,A20)
A21: Traffic Sign | B21: =COUNTIF(Annotation_Data!E2:E501,A21)
A22: Traffic Light | B22: =COUNTIF(Annotation_Data!E2:E501,A22)

Sheet Project_Guide
A1: Project | B1: Autonomous Driving Object Annotation Tracker
A2: Objective | B2: Track object labels, task status, QA findings, and annotation progress using Excel.
A3: Dataset | B3: 60 fictional sample task records. This is a practice dataset, not real employer data.
A4: Core Excel skills | B4: Excel Tables, filters, data validation, COUNTIF/COUNTIFS, PivotTables (optional), charts, conditional formatting.
A5: Suggested KPIs | B5: Total tasks, completed tasks, pending tasks, rejected tasks, QA pass rate, bounding-box completeness.
A6: Interview explanation | B6: I built an Excel tracker using fictional autonomous-driving annotation records. It standardizes object classes and task status, flags quality issues, and summarizes progress with KPI formulas and charts.
A7: Important | B7: Do not claim this was used at a previous employer. Explain that it is a self-directed portfolio project.
